Workbook

Sheet All Endpoints
A1: Ballys / Bellagio Reservation App – API Endpoints, IIDs and Screens | H1: Total APIs: | I1: =COUNTA(A5:A188)
A2: Source: lib/ folder of ballys-reservation-v2 (branch anu-v6), read on 2026-10-21. IID = value sent as "@Iid" to CommonExecute. "/" separates IIDs picked by tab, type or property. Server names are explained on the "Servers" sheet.
A4: No | B4: Module | C4: Screen | D4: Who Has Access | E4: Screen File(s) | F4: Method | G4: Endpoint | H4: IID | I4: What it does | J4: Code (file → function) | K4: Server | L4: Notes
A5: 1 | B5: Login & App Start | C5: Login, Settings | D5: Anyone (before login) | E5: lib/screens/auth/login_screen.dart lib/screens/settings_screen.dart | F5: POST | G5: Login | H5: — | I5: Get API access token (also used for biometric login) | J5: auth_repository.dart → authenticate() | K5: CRM API
A6: 2 | B6: Login & App Start | C6: Login | D6: Anyone (before login) | E6: lib/screens/auth/login_screen.dart | F6: POST | G6: CommonExecute | H6: 90144 | I6: User login (username / password check) | J6: auth_repository.dart → login() | K6: CRM API
A7: 3 | B7: Login & App Start | C7: OTP Verification, Login | D7: Every user, right after OTP login. Result (ReturnSatetus) = True lets the user open any member on the Members screen | E7: lib/screens/auth/otpVerification_screen.dart lib/screens/auth/login_screen.dart | F7: POST | G7: CommonExecute | H7: 646 | I7: Check whether the user has unrestricted access | J7: auth_repository.dart → fetchAccessStatus() (via auth_provider.completeLoginAfterOTP) | K7: CRM API | L7: Runs right after the OTP login completes
A8: 4 | B8: Login & App Start | C8: Settings | D8: All logged-in users (Settings → Delete Account) | E8: lib/screens/settings_screen.dart | F8: POST | G8: CommonExecute | H8: 90145 | I8: Delete user account | J8: auth_repository.dart → deleteAccount() | K8: CRM API
A9: 5 | B9: Login & App Start | C9: OTP Verification | D9: Anyone logging in (OTP step) | E9: lib/screens/auth/otpVerification_screen.dart | F9: POST | G9: https://api.ballyscolombo.com/api/Ballys/CRM/send-whatsapp | H9: — | I9: Send login OTP by WhatsApp | J9: auth_repository.dart → sendOtpWhatsApp() | K9: Full URL (hard-coded) | L9: URL is hard-coded to Ballys
A10: 6 | B10: Login & App Start | C10: OTP Verification | D10: Anyone logging in (OTP step) | E10: lib/screens/auth/otpVerification_screen.dart | F10: GET | G10: {SMS gateway URL from device config} | H10: — | I10: Send login OTP by SMS | J10: otpVerification_screen.dart → _sendOTPSMS() | K10: SMS Gateway | L10: URL comes from StorageUtil.getSmsGatewayUrl()
A11: 7 | B11: Login & App Start | C11: App Start (Splash), Login | D11: Every device (no login needed) | E11: lib/main.dart lib/screens/auth/login_screen.dart | F11: POST | G11: https://analyticshubapi.bty.world/api/device/log | H11: — | I11: Device config / log – returns the property API URL, SP name, etc. | J11: device_config_service.dart → fetchDeviceConfig() | K11: Device Config API
A12: 8 | B12: Login & App Start | C12: App Start (Splash) | D12: Every device (no login needed) | E12: lib/main.dart | F12: POST | G12: ApiVersion_CRM | H12: Platform 3 = Android, 4 = iOS | I12: App version check / force update | J12: versioncehck_service.dart → checkVersion() | K12: Version Check API | L12: Ballys: https://api.ballyscolombo.com/api/Ballys/ApiVersion_CRM | Bellagio: https://bty.world/api/Bellagio/CRM/ApiVersion_CRM
A13: 9 | B13: Login & App Start | C13: All screens (automatic) | D13: Automatic for any logged-in user | E13: — | F13: POST | G13: Login | H13: — | I13: Refresh expired token (on HTTP 401 / 406 "invalid token") and retry once | J13: token_manager.dart → _doRefresh() | K13: CRM API
A14: 10 | B14: Home | C14: Home (Dashboard) | D14: All logged-in users | E14: lib/screens/home_screen.dart | F14: POST | G14: CommonExecute | H14: 10001 | I14: Get run date (business date) | J14: run_date_repository.dart → getRunDate() | K14: CRM API
A15: 11 | B15: Home | C15: Home (Dashboard) | D15: All logged-in users see the counts. Tapping Today / Yesterday / Monthly: User Level 3 → Access Denied; Level 1 → sales-person breakdown; other levels → member visit list. Data: AD001 can switch to Overall Data (everyone); all others see only their own data (My Data). Opening a member: AD001 = any member; others = only members of their own marketing group | E15: lib/screens/home_screen.dart | F15: POST | G15: CommonExecute | H15: 9009 / 9010 / 9011 | I15: Guest list – 9009 Today, 9010 Yesterday, 9011 Monthly | J15: guest_repository.dart → getGuestData2() (via guests_provider) | K15: CRM API
A16: 12 | B16: Home | C16: Home (Dashboard), Marketing Details | D16: All logged-in users see the card. User Level 3 → Access Denied on tab change and drill-down. Data: AD001 can switch to Overall Data (everyone); all others see only their own data (My Data). Opening a member: AD001 = any member; others = only members of their own marketing group. "Other Marketing": Bellagio AD001 only | E16: lib/screens/home_screen.dart lib/screens/marketing_detail_page.dart | F16: POST | G16: CommonExecute | H16: 8896 / 8897 / 8898 / 8899 | I16: Marketing performance – 8896 Today, 8897 Yesterday, 8898 This Month, 8899 Last Month | J16: marketing_repository.dart → getMarketingData() (via marketing_provider) | K16: CRM API | L16: Home → Marketing Performance card
A17: 13 | B17: Home | C17: Home (Dashboard), Marketing Target Details | D17: All logged-in users see the card. User Level 3 → Access Denied on drill-down. Data: AD001 can switch to Overall Data (everyone); all others see only their own data (My Data). Opening a member: AD001 = any member; others = only members of their own marketing group | E17: lib/screens/home_screen.dart lib/screens/marketing_target_detail_page.dart | F17: POST | G17: CommonExecute | H17: 778898 / 558899 | I17: Marketing target – 778898 Monthly, 558899 Last Month | J17: marketing_repository.dart → getTargetData() | K17: CRM API | L17: Home → Marketing Performance card (Target view)
A18: 14 | B18: Home | C18: Home (Dashboard), Last 3 Months Details | D18: All logged-in users see the card. User Level 3 → Access Denied on refresh / drill-down. Data: AD001 can switch to Overall Data (everyone); all others see only their own data (My Data). Opening a member: AD001 = any member; others = only members of their own marketing group | E18: lib/screens/home_screen.dart lib/screens/last_three_months_detail_page.dart | F18: POST | G18: CommonExecute | H18: 778899 | I18: Last 3 months report | J18: last_three_months_repository.dart → getLastThreeMonthsData() | K18: CRM API | L18: Home → Last 3 Months card
A19: 15 | B19: Home | C19: Home (Dashboard), My Inactive Members, Inactive Members (Main) | D19: Ballys only, not shown to Level 3. Each user sees only their own inactive members (marketing code) | E19: lib/screens/home_screen.dart lib/screens/my_inactive_members_screen.dart lib/screens/Inactive_memberMain.dart | F19: POST | G19: CommonExecute | H19: 885263 | I19: Logged-in user's own inactive members | J19: inactive_members_repository.dart → getMyInactiveMembers() | K19: CRM API | L19: Ballys only. Home shows it as the "My Inactive" banner
A20: 16 | B20: Home | C20: Inactive Members | D20: Menu → Inactive Members (User Level 3 → Access Denied). Ballys: every member returned. Bellagio: AD001 and "MKT CC" see all; others only their own marketing group | E20: lib/screens/inactive_members.dart | F20: POST | G20: CommonExecute | H20: 1059006 (Ballys) / 9006 (Bellagio) | I20: Inactive members list + marketing group summary | J20: inactive_members_repository.dart → getInactiveMembers() | K20: CRM API
A21: 17 | B21: Home | C21: Menu (My Analytics), Reservations (Main), Approvals | D21: All logged-in users (badge counts) | E21: lib/screens/menu_screen.dart lib/screens/reservations/main_reservation.dart lib/screens/approve_reject_show_screen.dart | F21: POST | G21: CommonExecute | H21: 88965 (Ballys) / 8896590 (Bellagio) | I21: Pending approval counts (badges) | J21: pending_repository.dart → getPendingCounts() | K21: CRM API
A22: 18 | B22: Home | C22: Menu (My Analytics), Reservations (Main), Approvals | D22: All logged-in users (badge counts, Ballys only) | E22: lib/screens/menu_screen.dart lib/screens/reservations/main_reservation.dart lib/screens/approve_reject_show_screen.dart | F22: GET | G22: StatusCounts/Get | H22: — | I22: Reservation status counts (badges) | J22: pending_repository.dart → _applyStatusCounts() | K22: CRM API | L22: Ballys only
A23: 19 | B23: Members / Guest | C23: Members, Change Marketer, New Gift Request, New Reservation, New Reservation (Ballys), Quick Reservation, Quick Reservation (Ballys), New Group Reservation, Coordinator Request, Add Transport, Add Transport (Ballys), Add Visa Request | D23: Anyone who can open the host screen (see Screen column). Members screen: Menu → Members (User Level 3 → Access Denied); opening a member: AD001, users with IID 646 = True, or own marketing group only | E23: lib/screens/members_screen.dart lib/screens/change_marketing_person_screen.dart lib/screens/gifts/new_gift_request.dart lib/screens/reservations/new_reservation_screen.dart lib/screens/reservations/new_reservationBallys_screen.dart lib/screens/reservations/quick_reservation_screen.dart lib/screens/reservations/quick_reservation_ballys.dart lib/screens/reservations/group_reservation_ballys_screen.dart lib/screens/reservations/coordinator_request_ballys_screen.dart lib/screens/reservations/transport_add_screen.dart lib/screens/reservations/transport_add_ballys_screen.dart lib/screens/reservations/visa_add_ballys_screen.dart | F23: POST | G23: CommonExecute | H23: 8002 / 8003 | I23: Search member – 8002 by Member ID, 8003 by Name | J23: guest_repository.dart → searchGuest() | K23: CRM API
A24: 20 | B24: Members / Guest | C24: New Reservation, New Reservation (Ballys), Quick Reservation, Quick Reservation (Ballys), Reservation View, Reservation View (Ballys), Add Transport, View Guest Booking, View Special Gift (Check / Approve), View Birthday Gift Request (Check / Approve) | D24: Anyone who can open the host screen (see Screen column) | E24: lib/screens/reservations/new_reservation_screen.dart lib/screens/reservations/new_reservationBallys_screen.dart lib/screens/reservations/quick_reservation_screen.dart lib/screens/reservations/quick_reservation_ballys.dart lib/screens/reservations/reservation_view_screen.dart lib/screens/reservations/reservation_view_screen_ballys.dart lib/screens/reservations/transport_add_screen.dart lib/screens/view_guest_booking.dart lib/screens/gifts/view_special_gift.dart lib/screens/viewBirthdayGiftRequest.dart | F24: POST | G24: CommonExecute | H24: 9021 | I24: Get one member by Member ID (fills the guest card) | J24: guest_repository.dart → searchGuest(9021, mid) | K24: CRM API
A25: 21 | B25: Members / Guest | C25: Marketing Details, Marketing Target Details, Last 3 Months Details, Transport Details, Follow-up Details, View Guest Booking | D25: Opening a member: AD001 = any member; others = only members of their own marketing group (others get Access Denied) | E25: lib/screens/marketing_detail_page.dart lib/screens/marketing_target_detail_page.dart lib/screens/last_three_months_detail_page.dart lib/screens/reservations/transport_view_screen.dart lib/screens/follow_up_view_screen.dart lib/screens/view_guest_booking.dart | F25: POST | G25: CommonExecute | H25: 9021 | I25: Load full guest data by Member ID before opening Guest Profile | J25: guest_repository.dart → getGuestData() (via selected_guest_provider.setSelectedGuestWithId) | K25: CRM API
A26: 22 | B26: Members / Guest | C26: Guest Profile, Member Summary, Trip History, Guest Performance, Gifts, Guest Gifts (Redeem), Birthday Gift Price Increase | D26: Anyone who can open the Guest Profile. Profile rule: AD001 = any member; Mem_Prof_SH true/empty = any member; Mem_Prof_SH false = only own marketing group (or group "W") | E26: lib/screens/profile/profile_screen.dart lib/screens/profile/member_summary_screen.dart lib/screens/profile/trip_history_screen.dart lib/screens/profile/guest_performance/guest_performance_screen.dart lib/screens/gifts/gifts_screen.dart lib/screens/gifts/guest_gifts_screen.dart lib/screens/birthday_gift_price_increase_screen.dart | F26: POST | G26: CommonExecute | H26: 9021 | I26: Get guest photo | J26: guest_repository.dart → fetchGuestImage() | K26: CRM API
A27: 23 | B27: Members / Guest | C27: Follow-up Details, View Guest Booking | D27: Anyone who can open the host screen (see Screen column) | E27: lib/screens/follow_up_view_screen.dart lib/screens/view_guest_booking.dart | F27: POST | G27: CommonExecute | H27: 9022 | I27: Get guest photo (follow-up / booking card) | J27: guest_repository.dart → fetchGuestImage() | K27: CRM API | L27: Same IID 9022 is also used for hotel costs (different screen)
A28: 24 | B28: Members / Guest | C28: Members, Gifts | D28: Menu → Members / Gifts (User Level 3 → Access Denied) | E28: lib/screens/members_screen.dart lib/screens/gifts/gifts_screen.dart | F28: POST | G28: CommonExecute | H28: 9031 | I28: Gift members list | J28: gifts_repository.dart → getGiftMembers() | K28: CRM API
A29: 25 | B29: Members / Guest | C29: Change Marketer | D29: Ballys only. Menu → Members → Change Marketer (User Level 3 → Access Denied) | E29: lib/screens/change_marketing_person_screen.dart | F29: POST | G29: marketer_change_Insert | H29: — | I29: Submit change-marketer request | J29: guest_repository.dart → changeMarketer() | K29: CRM API
A30: 26 | B30: Members / Guest | C30: Marketer Change List | D30: Ballys only. Menu → Members (User Level 3 → Access Denied). AD001 sees all requests; others only their own marketing code | E30: lib/screens/marketer_change_list_screen.dart | F30: GET | G30: GetAllMarketerChange?marketingCodes={code} | H30: — | I30: List marketer change requests (AD001 sees all) | J30: guest_repository.dart → getAllMarketerChanges() | K30: CRM API
A31: 27 | B31: Guest Profile | C31: Guest Profile | D31: Anyone who can open the Guest Profile. Profile rule: AD001 = any member; Mem_Prof_SH true/empty = any member; Mem_Prof_SH false = only own marketing group (or group "W") | E31: lib/screens/profile/profile_screen.dart | F31: POST | G31: CommonExecute | H31: 9030 | I31: Member main profile details | J31: member_profile_repository.dart → getMemberMainProfileDetails() | K31: CRM API
A32: 28 | B32: Guest Profile | C32: Member Summary, Guest Profile | D32: Anyone who can open the Guest Profile. Profile rule: AD001 = any member; Mem_Prof_SH true/empty = any member; Mem_Prof_SH false = only own marketing group (or group "W") | E32: lib/screens/profile/member_summary_screen.dart lib/screens/profile/profile_screen.dart | F32: POST | G32: CommonExecute | H32: 9020 | I32: Member summary | J32: member_profile_repository.dart → getMemberSummary() | K32: CRM API
A33: 29 | B33: Guest Profile | C33: Guest Performance | D33: Anyone who can open the Guest Profile. Profile rule: AD001 = any member; Mem_Prof_SH true/empty = any member; Mem_Prof_SH false = only own marketing group (or group "W") | E33: lib/screens/profile/guest_performance/guest_performance_screen.dart | F33: POST | G33: GetLoyalitySummary | H33: — | I33: Loyalty summary (playerId, DateFrom, DateTo) | J33: member_profile_repository.dart → getLoyalitySummary() | K33: CRM API
A34: 30 | B34: Guest Profile | C34: Guest Performance | D34: Anyone who can open the Guest Profile. Profile rule: AD001 = any member; Mem_Prof_SH true/empty = any member; Mem_Prof_SH false = only own marketing group (or group "W") | E34: lib/screens/profile/guest_performance/guest_performance_screen.dart | F34: POST | G34: GetVisitFrequency | H34: — | I34: Trip information / visit frequency | J34: member_profile_repository.dart → getTripHistory() | K34: CRM API
A35: 31 | B35: Guest Profile | C35: Guest Performance | D35: Anyone who can open the Guest Profile. Profile rule: AD001 = any member; Mem_Prof_SH true/empty = any member; Mem_Prof_SH false = only own marketing group (or group "W") | E35: lib/screens/profile/guest_performance/guest_performance_screen.dart | F35: POST | G35: GetVisitFrequency2 | H35: — | I35: Trip information for a date range | J35: member_profile_repository.dart → getTripHistory2() | K35: CRM API
A36: 32 | B36: Guest Profile | C36: Trip History | D36: Anyone who can open the Guest Profile. Profile rule: AD001 = any member; Mem_Prof_SH true/empty = any member; Mem_Prof_SH false = only own marketing group (or group "W") | E36: lib/screens/profile/trip_history_screen.dart | F36: POST | G36: GetVisitFrequency_V2 | H36: Body "IID": 0 / 1 / 2 | I36: Trip history – 0 Date range, 1 Last 5 trips, 2 Last trip | J36: member_profile_repository.dart → getTripHistory3() | K36: CRM API | L36: IID is sent in the JSON body, not as @Iid
A37: 33 | B37: Guest Profile | C37: Guest Performance | D37: Anyone who can open the Guest Profile. Profile rule: AD001 = any member; Mem_Prof_SH true/empty = any member; Mem_Prof_SH false = only own marketing group (or group "W") | E37: lib/screens/profile/guest_performance/guest_performance_screen.dart | F37: POST | G37: GetTravelHistory | H37: — | I37: Air ticket history (Airlines) | J37: member_profile_repository.dart → getAirlineHistory() | K37: CRM API
A38: 34 | B38: Guest Profile | C38: Guest Performance | D38: Anyone who can open the Guest Profile. Profile rule: AD001 = any member; Mem_Prof_SH true/empty = any member; Mem_Prof_SH false = only own marketing group (or group "W") | E38: lib/screens/profile/guest_performance/guest_performance_screen.dart | F38: POST | G38: GetTravelHistory | H38: — | I38: Hotel reservation history (Hotels) | J38: member_profile_repository.dart → getHotelHistory() | K38: CRM API
A39: 35 | B39: Guest Profile | C39: Guest Performance | D39: Anyone who can open the Guest Profile. Profile rule: AD001 = any member; Mem_Prof_SH true/empty = any member; Mem_Prof_SH false = only own marketing group (or group "W") | E39: lib/screens/profile/guest_performance/guest_performance_screen.dart | F39: POST | G39: GetNonGamingActivities | H39: — | I39: F&B history | J39: member_profile_repository.dart → getFAndBHistory() | K39: CRM API
A40: 36 | B40: Guest Profile | C40: Guest Performance | D40: Anyone who can open the Guest Profile. Profile rule: AD001 = any member; Mem_Prof_SH true/empty = any member; Mem_Prof_SH false = only own marketing group (or group "W") | E40: lib/screens/profile/guest_performance/guest_performance_screen.dart | F40: POST | G40: GetGamingActivities | H40: — | I40: Games summary | J40: member_profile_repository.dart → getGamesSummary() | K40: CRM API
A41: 37 | B41: Guest Profile | C41: Guest Profile | D41: Anyone who can open the Guest Profile. Profile rule: AD001 = any member; Mem_Prof_SH true/empty = any member; Mem_Prof_SH false = only own marketing group (or group "W") | E41: lib/screens/profile/profile_screen.dart | F41: POST | G41: CommonExecute | H41: 8030 / 8031 / 8032 | I41: Add / update phone – 8030 Phone 1, 8031 Phone 2, 8032 Phone 3 | J41: phone_repository.dart → addPhoneNumber() | K41: CRM API | L41: Add Phone dialog
...

Sheet Access Rules
A1: Who has access – how the app decides
A2: All of these come from the login response (IID 90144) and the device config, saved on the phone after OTP. The app checks them on the screen; the server is only asked for a narrower list where noted.
A4: Permission | B4: Login field / source | C4: Value that matters | D4: What it allows | E4: Checked in
A5: Property | B5: Device config → API URL | C5: bty.world = Bellagio, otherwise Ballys | D5: Decides which screens exist. Ballys only: Group Reservation, Amendments, Coordinator, Transport / Visa / Airport Services (Ballys), Duty Manager, Change Marketer, My Inactive Members. Bellagio only: Transport (old) and the per-group filters on Birthdays / Daily Walking / Inactive | E5: menu_screen, main_reservation, membersMainScreen, Inactive_memberMain
A6: User Level | B6: User_Level | C6: 3 | D6: Restricted user. Gets "Access Denied" on: Package Guest, Approvals, Birthdays, Inactive Members, Members, Gifts, Daily Walking, Guest Bookings, Duty Manager; Reservations tiles (Reservations, Quick, Group, Amendments, Transport, Visa, Airport Services); Home count boxes, Marketing and Last 3 Months drill-downs. Can still use Home, Chat, Settings, Coordinator list, Transport (Bellagio) | E6: menu_screen, main_reservation, home_screen, marketing_performance, lastThreemonth
A7: User Level | B7: User_Level | C7: 1 | D7: Home Today / Yesterday / Monthly opens the "All Sales Persons" breakdown instead of a member list | E7: home_screen
A8: Admin sales code | B8: Sales_Code | C8: AD001 | D8: Admin. Overall Data switch, every member profile, every reservation / gift / amendment / transport / group request, every marketer change, share any follow-up PDF. Bellagio: "Other Marketing" group | E8: everywhere (StorageUtil.isAdminSalesCode)
A9: Call-centre code | B9: Sales_Code | C9: MKT CC | D9: Bellagio Inactive Members: sees every member (not just own group) | E9: inactive_members
A10: Marketing group | B10: Marketing_Code | C10: own code (0 = no group) | D10: Non-admin users only see / open members whose group matches this code. Lists from the server are filtered by it (Transport / Visa / Airport / Group / Marketer change). 0 = no "My Data" | E10: members, profile, marketing pages, repositories
A11: Marketing permission | B11: MArketing_P | C11: true | D11: "My Data" is filtered by Marketing_Code instead of Sales_Code | E11: StorageUtil.getDataScopeCode
A12: Member profile access | B12: Mem_Prof_SH | C12: false | D12: Guest Profile opens only for members of the user's own marketing group (or group "W"). true / empty = any member | E12: profile_screen
A13: Unrestricted access | B13: IID 646 → ReturnSatetus | C13: True | D13: Members screen lets the user open any member | E13: members_screen
A14: Reservation checker | B14: R_Chk | C14: true | D14: Sees all reservations, amendments, transport / visa / airport / group requests (Ballys). Check or Reject Pending. Reverse | E14: reservation, amendment, transport, visa, airport, group screens
A15: Reservation approver | B15: R_App | C15: true | D15: Sees all of the above. Approve or Reject Checked. Reverse | E15: same as R_Chk
... A24: Gift_App | B24: Gift_App | C24: — | D24: Saved at login but not checked anywhere in the app | E24: —

Sheet IID List
A1: IID List (CommonExecute "@Iid" values)
A3: IID | B3: What it does | C3: Endpoint | D3: Screen | E3: Who Has Access | F3: Code (file → function) | G3: Row in "All Endpoints"
A4: 641 | B4: Contact persons list | C4: CommonExecute | D4: Air Ticket Selection, New Reservation (Ballys), Quick Reservation, Quick Reservation (Ballys) | E4: Anyone who can open the reservation screens (Menu → Reservations – User Level 3 → Access Denied) | F4: contact_person_repository.dart → getContactPersons() | G4: =HYPERLINK("#'All Endpoints'!A100","Row "&'All Endpoints'!A100)
A5: 645 | B5: Get Academy web page URL | C5: CommonExecute | D5: Academy | E5: Not reachable right now – the Academy menu item is commented out (route /academic still exists) | F5: academic_repository.dart → getAcademicUrl() | G5: =HYPERLINK("#'All Endpoints'!A52","Row "&'All Endpoints'!A52)
A6: 646 | B6: Check whether the user has unrestricted access | C6: CommonExecute | D6: OTP Verification, Login | E6: Every user, right after OTP login. Result (ReturnSatetus) = True lets the user open any member on the Members screen | F6: auth_repository.dart → fetchAccessStatus() (via auth_provider.completeLoginAfterOTP) | G6: =HYPERLINK("#'All Endpoints'!A7","Row "&'All Endpoints'!A7)
A7: 647 | B7: On-duty managers list | C7: CommonExecute | D7: Duty Manager | E7: Ballys only. Menu → Duty Manager (User Level 3 → Access Denied) | F7: duty_manager_repository.dart → getOnDutyManagers() | G7: =HYPERLINK("#'All Endpoints'!A51","Row "&'All Endpoints'!A51)
A8: 7576 | B8: Package guest air tickets – Recent | C8: CommonExecute | D8: Package Guest (Air Tickets) | E8: Menu → Package Guest (User Level 3 → Access Denied) | F8: air_ticket_repository.dart → getRecentAirTickets() / getPastAirTickets() | G8: =HYPERLINK("#'All Endpoints'!A53","Row "&'All Endpoints'!A53)
A9: 7577 | B9: Package guest air tickets – Past | C9: CommonExecute | D9: Package Guest (Air Tickets) | E9: Menu → Package Guest (User Level 3 → Access Denied) | F9: air_ticket_repository.dart → getRecentAirTickets() / getPastAirTickets() | G9: =HYPERLINK("#'All Endpoints'!A53","Row "&'All Endpoints'!A53)
A10: 8002 | B10: Search member – by Member ID | C10: CommonExecute | D10: Members, Change Marketer, New Gift Request, New Reservation, New Reservation (Ballys), Quick Reservation, Quick Reservation (Ballys), New Group Reservation, Coordinator Request, Add Transport, Add Transport (Ballys), Add Visa Request | E10: Anyone who can open the host screen (see Screen column). Members screen: Menu → Members (User Level 3 → Access Denied); opening a member: AD001, users with IID 646 = True, or own marketing group only | F10: guest_repository.dart → searchGuest() | G10: =HYPERLINK("#'All Endpoints'!A23","Row "&'All Endpoints'!A23)
A11: 8003 | B11: Search member – by Name | C11: CommonExecute | D11: Members, Change Marketer, New Gift Request, New Reservation, New Reservation (Ballys), Quick Reservation, Quick Reservation (Ballys), New Group Reservation, Coordinator Request, Add Transport, Add Transport (Ballys), Add Visa Request | E11: Anyone who can open the host screen (see Screen column). Members screen: Menu → Members (User Level 3 → Access Denied); opening a member: AD001, users with IID 646 = True, or own marketing group only | F11: guest_repository.dart → searchGuest() | G11: =HYPERLINK("#'All Endpoints'!A23","Row "&'All Endpoints'!A23)
A12: 8030 | B12: Add / update phone – Phone 1 | C12: CommonExecute | D12: Guest Profile | E12: Anyone who can open the Guest Profile. Profile rule: AD001 = any member; Mem_Prof_SH true/empty = any member; Mem_Prof_SH false = only own marketing group (or group "W") | F12: phone_repository.dart → addPhoneNumber() | G12: =HYPERLINK("#'All Endpoints'!A41","Row "&'All Endpoints'!A41)
A13: 8031 | B13: Add / update phone – Phone 2 | C13: CommonExecute | D13: Guest Profile | E13: Anyone who can open the Guest Profile. Profile rule: AD001 = any member; Mem_Prof_SH true/empty = any member; Mem_Prof_SH false = only own marketing group (or group "W") | F13: phone_repository.dart → addPhoneNumber() | G13: =HYPERLINK("#'All Endpoints'!A41","Row "&'All Endpoints'!A41)
A14: 8032 | B14: Add / update phone – Phone 3 | C14: CommonExecute | D14: Guest Profile | E14: Anyone who can open the Guest Profile. Profile rule: AD001 = any member; Mem_Prof_SH true/empty = any member; Mem_Prof_SH false = only own marketing group (or group "W") | F14: phone_repository.dart → addPhoneNumber() | G14: =HYPERLINK("#'All Endpoints'!A41","Row "&'All Endpoints'!A41)
A15: 8033 | B15: Add / update email – Email 1 | C15: CommonExecute | D15: Guest Profile | E15: Anyone who can open the Guest Profile. Profile rule: AD001 = any member; Mem_Prof_SH true/empty = any member; Mem_Prof_SH false = only own marketing group (or group "W") | F15: email_repository.dart → addOrUpdateEmail() | G15: =HYPERLINK("#'All Endpoints'!A42","Row "&'All Endpoints'!A42)
A16: 8034 | B16: Add / update email – Email 2 | C16: CommonExecute | D16: Guest Profile | E16: Anyone who can open the Guest Profile. Profile rule: AD001 = any member; Mem_Prof_SH true/empty = any member; Mem_Prof_SH false = only own marketing group (or group "W") | F16: email_repository.dart → addOrUpdateEmail() | G16: =HYPERLINK("#'All Endpoints'!A42","Row "&'All Endpoints'!A42)
A17: 8035 | B17: Add / update WhatsApp – No 1 | C17: CommonExecute | D17: Guest Profile | E17: Anyone who can open the Guest Profile. Profile rule: AD001 = any member; Mem_Prof_SH true/empty = any member; Mem_Prof_SH false = only own marketing group (or group "W") | F17: whatsapp_number_repository.dart → addWhatsAppNumber() | G17: =HYPERLINK("#'All Endpoints'!A43","Row "&'All Endpoints'!A43)
A18: 8036 | B18: Add / update WhatsApp – No 2 | C18: CommonExecute | D18: Guest Profile | E18: Anyone who can open the Guest Profile. Profile rule: AD001 = any member; Mem_Prof_SH true/empty = any member; Mem_Prof_SH false = only own marketing group (or group "W") | F18: whatsapp_number_repository.dart → addWhatsAppNumber() | G18: =HYPERLINK("#'All Endpoints'!A43","Row "&'All Endpoints'!A43)
A19: 8037 | B19: Add / update WhatsApp – No 3 | C19: CommonExecute | D19: Guest Profile | E19: Anyone who can open the Guest Profile. Profile rule: AD001 = any member; Mem_Prof_SH true/empty = any member; Mem_Prof_SH false = only own marketing group (or group "W") | F19: whatsapp_number_repository.dart → addWhatsAppNumber() | G19: =HYPERLINK("#'All Endpoints'!A43","Row "&'All Endpoints'!A43)
A20: 8038 | B20: Set primary contact – Phone | C20: CommonExecute | D20: Guest Profile | E20: Anyone who can open the Guest Profile. Profile rule: AD001 = any member; Mem_Prof_SH true/empty = any member; Mem_Prof_SH false = only own marketing group (or group "W") | F20: primary_contact_repository.dart → setPrimaryPhone / Email / WhatsApp() | G20: =HYPERLINK("#'All Endpoints'!A44","Row "&'All Endpoints'!A44)
A21: 8039 | B21: Set primary contact – Email | C21: CommonExecute | D21: Guest Profile | E21: Anyone who can open the Guest Profile. Profile rule: AD001 = any member; Mem_Prof_SH true/empty = any member; Mem_Prof_SH false = only own marketing group (or group "W") | F21: primary_contact_repository.dart → setPrimaryPhone / Email / WhatsApp() | G21: =HYPERLINK("#'All Endpoints'!A44","Row "&'All Endpoints'!A44)
A22: 8040 | B22: Set primary contact – WhatsApp | C22: CommonExecute | D22: Guest Profile | E22: Anyone who can open the Guest Profile. Profile rule: AD001 = any member; Mem_Prof_SH true/empty = any member; Mem_Prof_SH false = only own marketing group (or group "W") | F22: primary_contact_repository.dart → setPrimaryPhone / Email / WhatsApp() | G22: =HYPERLINK("#'All Endpoints'!A44","Row "&'All Endpoints'!A44)
A23: 8875 | B23: Member's birthday gift details | C23: CommonExecute | D23: Guest Profile, View Special Gift (Check / Approve), View Birthday Gift Request (Check / Approve) | E23: Guest Profile users (profile rule) and gift checkers / approvers on the gift view screens | F23: birthday_gift_repository.dart → getBirthdayGift() | G23: =HYPERLINK("#'All Endpoints'!A45","Row "&'All Endpoints'!A45)
A24: 8886 | B24: Guest's gift history for a date range | C24: CommonExecute | D24: New Gift Request, Birthday Gift Price Increase | E24: Anyone who can open New Gift Request (Gifts / Approvals menu – User Level 3 → Access Denied) | F24: gifts_repository.dart → getgestgiftGift() | G24: =HYPERLINK("#'All Endpoints'!A66","Row "&'All Endpoints'!A66)
A25: 8887 | B25: Gift types (gift-for dropdown) | C25: CommonExecute | D25: New Gift Request, Birthday Gift Price Increase, View Special Gift (Check / Approve) | E25: Anyone who can open New Gift Request (Gifts / Approvals menu – User Level 3 → Access Denied) | F25: gifts_repository.dart → getGiftForList() | G25: =HYPERLINK("#'All Endpoints'!A67","Row "&'All Endpoints'!A67)
A26: 8888 | B26: Previous gifts – normal | C26: CommonExecute | D26: Previous Gifts, View Special Gift (Check / Approve), View Birthday Gift Request (Check / Approve) | E26: Anyone who can open the host screen (see Screen column) | F26: gifts_repository.dart → getPrvGiftList() | G26: =HYPERLINK("#'All Endpoints'!A68","Row "&'All Endpoints'!A68)
A27: 8890 | B27: Get pending gift by member ID (not used) | C27: CommonExecute | D27: Not used (no screen calls it) | E27: Nobody – not called from any screen | F27: gifts_repository.dart → getPendingGiftByMid() | G27: =HYPERLINK("#'All Endpoints'!A87","Row "&'All Endpoints'!A87)
A28: 8890 | B28: Special gift requests – Pending | C28: CommonExecute | D28: Special Gift Requests, New Gift Request | E28: Menu → Approvals → Special Gift Requests (User Level 3 → Access Denied). AD001, G_CHK and G_App see all; others only their own requests. Opening: Pending = G_CHK or requester; Checked / Approved = G_App, requester, checker / approver; Issued = G_App, G_CHK or requester; Rejected = requester or rejecter | F28: gifts_repository.dart → getSpecialGift() (via special_gift_provider) | G28: =HYPERLINK("#'All Endpoints'!A65","Row "&'All Endpoints'!A65)
A29: 8891 | B29: Special gift requests – Approved | C29: CommonExecute | D29: Special Gift Requests, New Gift Request | E29: Menu → Approvals → Special Gift Requests (User Level 3 → Access Denied). AD001, G_CHK and G_App see all; others only their own requests. Opening: Pending = G_CHK or requester; Checked / Approved = G_App, requester, checker / approver; Issued = G_App, G_CHK or requester; Rejected = requester or rejecter | F29: gifts_repository.dart → getSpecialGift() (via special_gift_provider) | G29: =HYPERLINK("#'All Endpoints'!A65","Row "&'All Endpoints'!A65)
A30: 8892 | B30: Reject special gift request | C30: CommonExecute | D30: View Special Gift (Check / Approve) | E30: Pending → G_CHK. Checked → G_App | F30: gifts_repository.dart → rejectSPecialgiftRequest() | G30: =HYPERLINK("#'All Endpoints'!A73","Row "&'All Endpoints'!A73)
A31: 8893 | B31: Special gift requests – Rejected | C31: CommonExecute | D31: Special Gift Requests, New Gift Request | E31: Menu → Approvals → Special Gift Requests (User Level 3 → Access Denied). AD001, G_CHK and G_App see all; others only their own requests. Opening: Pending = G_CHK or requester; Checked / Approved = G_App, requester, checker / approver; Issued = G_App, G_CHK or requester; Rejected = requester or rejecter | F31: gifts_repository.dart → getSpecialGift() (via special_gift_provider) | G31: =HYPERLINK("#'All Endpoints'!A65","Row "&'All Endpoints'!A65)
A32: 8894 | B32: Approve special gift request | C32: CommonExecute | D32: View Special Gift (Check / Approve) | E32: G_App (special gift approver) – Checked tab | F32: gifts_repository.dart → approvedSPecialgiftRequest() | G32: =HYPERLINK("#'All Endpoints'!A72","Row "&'All Endpoints'!A72)
A33: 8895 | B33: Daily walking guests list | C33: CommonExecute | D33: Daily Walking Guests | E33: Menu → Daily Walking Guests (User Level 3 → Access Denied). Ballys: everyone. Bellagio: AD001 all; others only own marketing group | F33: daily_walking_repository.dart → getAllgest() | G33: =HYPERLINK("#'All Endpoints'!A50","Row "&'All Endpoints'!A50)
A34: 8896 | B34: Marketing performance – Today | C34: CommonExecute | D34: Home (Dashboard), Marketing Details | E34: All logged-in users see the card. User Level 3 → Access Denied on tab change and drill-down. Data: AD001 can switch to Overall Data (everyone); all others see only their own data (My Data). Opening a member: AD001 = any member; others = only members of their own marketing group. "Other Marketing": Bellagio AD001 only | F34: marketing_repository.dart → getMarketingData() (via marketing_provider) | G34: =HYPERLINK("#'All Endpoints'!A16","Row "&'All Endpoints'!A16)
A35: 8897 | B35: Marketing performance – Yesterday | C35: CommonExecute | D35: Home (Dashboard), Marketing Details | E35: All logged-in users see the card. User Level 3 → Access Denied on tab change and drill-down. Data: AD001 can switch to Overall Data (everyone); all others see only their own data (My Data). Opening a member: AD001 = any member; others = only members of their own marketing group. "Other Marketing": Bellagio AD001 only | F35: marketing_repository.dart → getMarketingData() (via marketing_provider) | G35: =HYPERLINK("#'All Endpoints'!A16","Row "&'All Endpoints'!A16)
A36: 8898 | B36: Marketing performance – This Month | C36: CommonExecute | D36: Home (Dashboard), Marketing Details | E36: All logged-in users see the card. User Level 3 → Access Denied on tab change and drill-down. Data: AD001 can switch to Overall Data (everyone); all others see only their own data (My Data). Opening a member: AD001 = any member; others = only members of their own marketing group. "Other Marketing": Bellagio AD001 only | F36: marketing_repository.dart → getMarketingData() (via marketing_provider) | G36: =HYPERLINK("#'All Endpoints'!A16","Row "&'All Endpoints'!A16)
A37: 8899 | B37: Marketing performance – Last Month | C37: CommonExecute | D37: Home (Dashboard), Marketing Details | E37: All logged-in users see the card. User Level 3 → Access Denied on tab change and drill-down. Data: AD001 can switch to Overall Data (everyone); all others see only their own data (My Data). Opening a member: AD001 = any member; others = only members of their own marketing group. "Other Marketing": Bellagio AD001 only | F37: marketing_repository.dart → getMarketingData() (via marketing_provider) | G37: =HYPERLINK("#'All Endpoints'!A16","Row "&'All Endpoints'!A16)
A38: 9004 | B38: Birthday list | C38: CommonExecute | D38: Birthdays | E38: Menu → Birthdays (User Level 3 → Access Denied). Ballys: every birthday. Bellagio: AD001 all; others only own marketing group | F38: birthday_repository.dart → getBirthdays() | G38: =HYPERLINK("#'All Endpoints'!A49","Row "&'All Endpoints'!A49)
A39: 9006 | B39: Inactive members list + marketing group summary (Bellagio) | C39: CommonExecute | D39: Inactive Members | E39: Menu → Inactive Members (User Level 3 → Access Denied). Ballys: every member returned. Bellagio: AD001 and "MKT CC" see all; others only their own marketing group | F39: inactive_members_repository.dart → getInactiveMembers() | G39: =HYPERLINK("#'All Endpoints'!A20","Row "&'All Endpoints'!A20)
A40: 9009 | B40: Guest list – Today | C40: CommonExecute | D40: Home (Dashboard) | E40: All logged-in users see the counts. Tapping Today / Yesterday / Monthly: User Level 3 → Access Denied; Level 1 → sales-person breakdown; other levels → member visit list. Data: AD001 can switch to Overall Data (everyone); all others see only their own data (My Data). Opening a member: AD001 = any member; others = only members of their own marketing group | F40: guest_repository.dart → getGuestData2() (via guests_provider) | G40: =HYPERLINK("#'All Endpoints'!A15","Row "&'All Endpoints'!A15)
A41: 9010 | B41: Guest list – Yesterday | C41: CommonExecute | D41: Home (Dashboard) | E41: All logged-in users see the counts. Tapping Today / Yesterday / Monthly: User Level 3 → Access Denied; Level 1 → sales-person breakdown; other levels → member visit list. Data: AD001 can switch to Overall Data (everyone); all others see only their own data (My Data). Opening a member: AD001 = any member; others = only members of their own marketing group | F41: guest_repository.dart → getGuestData2() (via guests_provider) | G41: =HYPERLINK("#'All Endpoints'!A15","Row "&'All Endpoints'!A15)
...

Sheet By Screen
A1: APIs used per screen
A3: Screen | B3: Screen File | C3: No. of APIs | D3: Endpoints (IID) | E3: Who Can Open / Use It
A4: Academy | B4: lib/screens/academic_screen.dart | C4: =COUNTIF('All Endpoints'!E:E,"*"&B4&"*") | D4: • POST CommonExecute [645] – Get Academy web page URL | E4: No menu entry at the moment
A5: Add Follow-up | B5: lib/screens/follow_screen.dart | C5: =COUNTIF('All Endpoints'!E:E,"*"&B5&"*") | D5: • POST followup_Insert – Save a follow-up | E5: Same as Guest Profile
A6: Add Transport | B6: lib/screens/reservations/transport_add_screen.dart | C6: =COUNTIF('All Endpoints'!E:E,"*"&B6&"*") | D6: • POST CommonExecute [8002 / 8003] – Search member – 8002 by Member ID, 8003 by Name • POST CommonExecute [9021] – Get one member by Member ID (fills the guest card) • GET Transport_Get_Data?salesCode={code} – Transport list (admin / approver gets all) • POST Transport_Insert – Add transport • POST v1/places:autocomplete – Place search (new Places API) • GET maps/api/place/autocomplete/json – Place search (legacy fallback) • GET maps/api/geocode/json – Geocode (map pin ↔ address) | E6: Bellagio, all levels
A7: Add Transport (Ballys) | B7: lib/screens/reservations/transport_add_ballys_screen.dart | C7: =COUNTIF('All Endpoints'!E:E,"*"&B7&"*") | D7: • POST CommonExecute [8002 / 8003] – Search member – 8002 by Member ID, 8003 by Name • GET GetAuthorizationLevels – Approver / authorization levels • POST TransportReservation/Insert – Save transport reservation (Ballys) • POST v1/places:autocomplete – Place search (new Places API) • GET maps/api/place/autocomplete/json – Place search (legacy fallback) • GET maps/api/geocode/json – Geocode (map pin ↔ address) | E7: Ballys, not Level 3
A8: Add Visa Request | B8: lib/screens/reservations/visa_add_ballys_screen.dart | C8: =COUNTIF('All Endpoints'!E:E,"*"&B8&"*") | D8: • POST CommonExecute [8002 / 8003] – Search member – 8002 by Member ID, 8003 by Name • POST VisaRequest/Insert – Save visa request | E8: Ballys, not Level 3
A9: Air Ticket Amendment | B9: lib/screens/reservations/air_ticket_amendment_ballys_screen.dart | C9: =COUNTIF('All Endpoints'!E:E,"*"&B9&"*") | D9: • POST CommonExecute [9018] – Airports list (airport search field) • POST AmendmentAir/Insert – Submit air ticket amendment | E9: Anyone viewing an Approved reservation
A10: Air Ticket Selection | B10: lib/screens/reservations/air_tickets_selection_screen.dart | C10: =COUNTIF('All Endpoints'!E:E,"*"&B10&"*") | D10: • POST CommonExecute [641] – Contact persons list • POST CommonExecute [9018] – Airports list (airport search field) • POST CommonExecute [9023] – Airport / air ticket costs • POST CommonExecute [9016] – Hotel room categories • POST CommonExecute [9017] – Hotel room types for a category | E10: Not Level 3
A11: Air Ticket Selection (Ballys) | B11: lib/screens/reservations/air_tickets_selection_ballys_screen.dart | C11: =COUNTIF('All Endpoints'!E:E,"*"&B11&"*") | D11: • POST CommonExecute [9018] – Airports list (airport search field) • POST CommonExecute [90156] – Airlines list • POST CommonExecute [9016] – Hotel room categories • POST CommonExecute [9017] – Hotel room types for a category | E11: Not Level 3
A12: Air Ticket Selection (Ballys, old) | B12: lib/screens/reservations/air_tickets_selection_screen_ballys.dart | C12: =COUNTIF('All Endpoints'!E:E,"*"&B12&"*") | D12: • POST CommonExecute [9018] – Airports list (airport search field) | E12: Not Level 3
A13: Airport Service Details | B13: lib/screens/reservations/airport_service_view_ballys_screen.dart | C13: =COUNTIF('All Endpoints'!E:E,"*"&B13&"*") | D13: • POST AirportService/UpdateStatus – Approve / reject airport service | E13: Pending → R_Chk (Check / Reject). Checked → R_App (Approve / Reject)
A14: Airport Services | B14: lib/screens/reservations/airport_service_ballys_screen.dart | C14: =COUNTIF('All Endpoints'!E:E,"*"&B14&"*") | D14: • GET AirportService/Get?marketingCode={code} – Airport services list | E14: Ballys only, User Level 3 → Access Denied. AD001, R_Chk and R_App see all; others see only their own marketing code
A15: Amendment View (Check / Approve) | B15: lib/screens/reservations/amendment_view_ballys_screen.dart | C15: =COUNTIF('All Endpoints'!E:E,"*"&B15&"*") | D15: • POST {AmendmentAir | AmendmentHotel | AmendmentPaymentBy}/{UpdateChecked | UpdateApproved | UpdateRejected} – Check / approve / reject an amendment | E15: Pending → R_Chk (Check / Reject). Checked → R_App (Approve / Reject)
... A82: Visa Requests | B82: lib/screens/reservations/visa_ballys_screen.dart | C82: =COUNTIF('All Endpoints'!E:E,"*"&B82&"*") | D82: • GET VisaRequest/Get?marketingCode={code} – Visa requests list | E82: Ballys only, User Level 3 → Access Denied. AD001, R_Chk and R_App see all; others see only their own marketing code

Sheet Servers
A1: Servers (base URLs)
A3: Server | B3: Ballys URL | C3: Bellagio URL | D3: How the app picks it | E3: Used by
A4: CRM API | B4: https://api.ballyscolombo.com/api/Ballys/CRM | C4: https://bty.world/api/Bellagio/CRM | D4: StorageUtil.getCurrentApiUrl() – saved from the device config at login. Requests go to {base}/{endpoint} with a Bearer token. | E4: All CommonExecute calls and every other relative endpoint
A5: Chat API | B5: https://chat.bcqr.lk | C5: https://chat.bty.world | D5: FirebaseApiService.resolveDomain() – by logged-in property | E5: Chat, groups, calls, FCM / VoIP tokens
A6: Gift WhatsApp API | B6: https://gift.myanalytics.lk/api | C6: (same) | D6: Constants.laravelAPIbaseUrl | E6: Gift / birthday WhatsApp messages and OTPs
A7: Device Config API | B7: https://analyticshubapi.bty.world/api/device/log | C7: (same) | D7: DeviceConfigService._configApiUrl | E7: App start and login
A8: Version Check API | B8: https://api.ballyscolombo.com/api/Ballys/ApiVersion_CRM | C8: https://bty.world/api/Bellagio/CRM/ApiVersion_CRM | D8: Constants.versionCheckUrl / bellagioVersionCheckUrl | E8: Force-update check at app start
A9: SMS Gateway | B9: (from device config) | C9: (from device config) | D9: StorageUtil.getSmsGatewayUrl() | E9: OTP SMS
A10: Google Maps API | B10: https://places.googleapis.com / https://maps.googleapis.com | C10: (same) | D10: places_service.dart | E10: Location search and map picker
